  0%|                                                                               | 0/500 [00:00<?, ?it/s]Traceback (most recent call last):
  File "/home/ubuntu/research/arc-agi/train.py", line 69, in <module>
    main()
  File "/home/ubuntu/research/arc-agi/train.py", line 63, in main
    trainer.train()
  File "/home/ubuntu/.venv/lib/python3.12/site-packages/transformers/trainer.py", line 2171, in train
    return inner_training_loop(
           ^^^^^^^^^^^^^^^^^^^^
  File "/home/ubuntu/.venv/lib/python3.12/site-packages/transformers/trainer.py", line 2531, in _inner_training_loop
    tr_loss_step = self.training_step(model, inputs, num_items_in_batch)
                   ^^^^^^^^^^^^^^^^^^^^^^^^^^^^^^^^^^^^^^^^^^^^^^^^^^^^^
  File "/home/ubuntu/.venv/lib/python3.12/site-packages/transformers/trainer.py", line 3669, in training_step
    inputs = self._prepare_inputs(inputs)
             ^^^^^^^^^^^^^^^^^^^^^^^^^^^^
  File "/home/ubuntu/.venv/lib/python3.12/site-packages/trl/trainer/grpo_trainer.py", line 548, in _prepare_inputs
    full_outputs = self.model.generate(
                   ^^^^^^^^^^^^^^^^^^^^
  File "/home/ubuntu/.venv/lib/python3.12/site-packages/torch/utils/_contextlib.py", line 116, in decorate_context
    return func(*args, **kwargs)
           ^^^^^^^^^^^^^^^^^^^^^
  File "/home/ubuntu/.venv/lib/python3.12/site-packages/transformers/generation/utils.py", line 2012, in generate
    self._validate_model_kwargs(model_kwargs.copy())
  File "/home/ubuntu/.venv/lib/python3.12/site-packages/transformers/generation/utils.py", line 1388, in _validate_model_kwargs
    raise ValueError(
ValueError: The following `model_kwargs` are not used by the model: ['sampling_params', 'use_tqdm'] (note: typos in the generate arguments will also show up in this list)
[rank0]: Traceback (most recent call last):
[rank0]:   File "/home/ubuntu/research/arc-agi/train.py", line 69, in <module>
[rank0]:     main()
[rank0]:   File "/home/ubuntu/research/arc-agi/train.py", line 63, in main
[rank0]:     trainer.train()
[rank0]:   File "/home/ubuntu/.venv/lib/python3.12/site-packages/transformers/trainer.py", line 2171, in train
[rank0]:     return inner_training_loop(
[rank0]:            ^^^^^^^^^^^^^^^^^^^^
[rank0]:   File "/home/ubuntu/.venv/lib/python3.12/site-packages/transformers/trainer.py", line 2531, in _inner_training_loop
[rank0]:     tr_loss_step = self.training_step(model, inputs, num_items_in_batch)
[rank0]:                    ^^^^^^^^^^^^^^^^^^^^^^^^^^^^^^^^^^^^^^^^^^^^^^^^^^^^^
[rank0]:   File "/home/ubuntu/.venv/lib/python3.12/site-packages/transformers/trainer.py", line 3669, in training_step
[rank0]:     inputs = self._prepare_inputs(inputs)
[rank0]:              ^^^^^^^^^^^^^^^^^^^^^^^^^^^^
[rank0]:   File "/home/ubuntu/.venv/lib/python3.12/site-packages/trl/trainer/grpo_trainer.py", line 548, in _prepare_inputs
[rank0]:     full_outputs = self.model.generate(
[rank0]:                    ^^^^^^^^^^^^^^^^^^^^
[rank0]:   File "/home/ubuntu/.venv/lib/python3.12/site-packages/torch/utils/_contextlib.py", line 116, in decorate_context
[rank0]:     return func(*args, **kwargs)
[rank0]:            ^^^^^^^^^^^^^^^^^^^^^
[rank0]:   File "/home/ubuntu/.venv/lib/python3.12/site-packages/transformers/generation/utils.py", line 2012, in generate
[rank0]:     self._validate_model_kwargs(model_kwargs.copy())
[rank0]:   File "/home/ubuntu/.venv/lib/python3.12/site-packages/transformers/generation/utils.py", line 1388, in _validate_model_kwargs
[rank0]:     raise ValueError(
[rank0]: ValueError: The following `model_kwargs` are not used by the model: ['sampling_params', 'use_tqdm'] (note: typos in the generate arguments will also show up in this list)
